test_avatar (__main__.UserModelCase) ... ok
test_follow (__main__.UserModelCase) ... ok
test_follow_posts (__main__.UserModelCase) ... ERROR
test_password_hashing (__main__.UserModelCase) ... ok

======================================================================
ERROR: test_follow_posts (__main__.UserModelCase)
----------------------------------------------------------------------
Traceback (most recent call last):
  File "/Users/mplilly/code/python/microblog/venv/lib/python3.7/site-packages/sqlalchemy/engine/base.py", line 1193, in _execute_context
    context)
  File "/Users/mplilly/code/python/microblog/venv/lib/python3.7/site-packages/sqlalchemy/engine/default.py", line 509, in do_execute
    cursor.execute(statement, parameters)
sqlite3.OperationalError: near "UNION": syntax error

The above exception was the direct cause of the following exception:

Traceback (most recent call last):
  File "tests.py", line 79, in test_follow_posts
    f1 = u1.followed_posts().all()
  File "/Users/mplilly/code/python/microblog/venv/lib/python3.7/site-packages/sqlalchemy/orm/query.py", line 2843, in all
    return list(self)
  File "/Users/mplilly/code/python/microblog/venv/lib/python3.7/site-packages/sqlalchemy/orm/query.py", line 2995, in __iter__
    return self._execute_and_instances(context)
  File "/Users/mplilly/code/python/microblog/venv/lib/python3.7/site-packages/sqlalchemy/orm/query.py", line 3018, in _execute_and_instances
    result = conn.execute(querycontext.statement, self._params)
  File "/Users/mplilly/code/python/microblog/venv/lib/python3.7/site-packages/sqlalchemy/engine/base.py", line 948, in execute
    return meth(self, multiparams, params)
  File "/Users/mplilly/code/python/microblog/venv/lib/python3.7/site-packages/sqlalchemy/sql/elements.py", line 269, in _execute_on_connection
    return connection._execute_clauseelement(self, multiparams, params)
  File "/Users/mplilly/code/python/microblog/venv/lib/python3.7/site-packages/sqlalchemy/engine/base.py", line 1060, in _execute_clauseelement
    compiled_sql, distilled_params
  File "/Users/mplilly/code/python/microblog/venv/lib/python3.7/site-packages/sqlalchemy/engine/base.py", line 1200, in _execute_context
    context)
  File "/Users/mplilly/code/python/microblog/venv/lib/python3.7/site-packages/sqlalchemy/engine/base.py", line 1413, in _handle_dbapi_exception
    exc_info
  File "/Users/mplilly/code/python/microblog/venv/lib/python3.7/site-packages/sqlalchemy/util/compat.py", line 265, in raise_from_cause
    reraise(type(exception), exception, tb=exc_tb, cause=cause)
  File "/Users/mplilly/code/python/microblog/venv/lib/python3.7/site-packages/sqlalchemy/util/compat.py", line 248, in reraise
    raise value.with_traceback(tb)
  File "/Users/mplilly/code/python/microblog/venv/lib/python3.7/site-packages/sqlalchemy/engine/base.py", line 1193, in _execute_context
    context)
  File "/Users/mplilly/code/python/microblog/venv/lib/python3.7/site-packages/sqlalchemy/engine/default.py", line 509, in do_execute
    cursor.execute(statement, parameters)
sqlalchemy.exc.OperationalError: (sqlite3.OperationalError) near "UNION": syntax error [SQL: 'SELECT anon_1.post_id AS anon_1_post_id, anon_1.post_body AS anon_1_post_body, anon_1.post_timestamp AS anon_1_post_timestamp, anon_1.post_user_id AS anon_1_post_user_id \nFROM ((SELECT post.id AS post_id, post.body AS post_body, post.timestamp AS post_timestamp, post.user_id AS post_user_id \nFROM post JOIN followers ON followers.followed_id = post.user_id \nWHERE followers.follower_id = ? ORDER BY post.timestamp DESC) UNION SELECT post.id AS post_id, post.body AS post_body, post.timestamp AS post_timestamp, post.user_id AS post_user_id \nFROM post \nWHERE post.user_id = ?) AS anon_1 ORDER BY anon_1.post_timestamp DESC'] [parameters: (1, 1)] (Background on this error at: http://sqlalche.me/e/e3q8)

----------------------------------------------------------------------
Ran 4 tests in 0.191s

FAILED (errors=1)
